reported_result/report-18/ART_WClustering/output/output14.txt

Limit	1	4	1	4	4	SELL	0	---	0
NewOrderRs	Accepted
	Trades	0
	Orders	1
	Order	Limit	1	4	1	4	4	SELL	0	---	0
	Credits	7
	Credit	1	16
	Credit	2	11
	Credit	3	10
	Credit	4	8
	Credit	5	10
	Credit	6	14
	Credit	7	12
	Ownerships	7
	Ownership	1	93
	Ownership	2	76
	Ownership	3	56
	Ownership	4	22
	Ownership	5	68
	Ownership	6	56
	Ownership	7	93
	ReferencePrice	5
	StaticPriceBandLowerLimit	0.6
	StaticPriceBandUpperLimit	0.8
	TotalShares	100
	OwnershipUpperLimit	0.2
	TickSize	1
	LotSize	1
Iceberg	2	1	6	3	8	BUY 	6	---	0
NewOrderRs	Rejected
	Trades	0
	Orders	1
	Order	Limit	1	4	1	4	4	SELL	0	---	0
	Credits	7
	Credit	1	16
	Credit	2	11
	Credit	3	10
	Credit	4	8
	Credit	5	10
	Credit	6	14
	Credit	7	12
	Ownerships	7
	Ownership	1	93
	Ownership	2	76
	Ownership	3	56
	Ownership	4	22
	Ownership	5	68
	Ownership	6	56
	Ownership	7	93
	ReferencePrice	5
	StaticPriceBandLowerLimit	0.6
	StaticPriceBandUpperLimit	0.8
	TotalShares	100
	OwnershipUpperLimit	0.2
	TickSize	1
	LotSize	1
Iceberg	3	2	3	7	2	SELL	0	---	0
NewOrderRs	Accepted
	Trades	0
	Orders	2
	Order	Limit	1	4	1	4	4	SELL	0	---	0
	Order	Iceberg	3	2	3	7	2	SELL	0	---	1
	Credits	7
	Credit	1	16
	Credit	2	11
	Credit	3	10
	Credit	4	8
	Credit	5	10
	Credit	6	14
	Credit	7	12
	Ownerships	7
	Ownership	1	93
	Ownership	2	76
	Ownership	3	56
	Ownership	4	22
	Ownership	5	68
	Ownership	6	56
	Ownership	7	93
	ReferencePrice	5
	StaticPriceBandLowerLimit	0.6
	StaticPriceBandUpperLimit	0.8
	TotalShares	100
	OwnershipUpperLimit	0.2
	TickSize	1
	LotSize	1
Iceberg	4	2	1	3	1	SELL	1	---	0
NewOrderRs	Eliminated
	Trades	0
	Orders	2
	Order	Limit	1	4	1	4	4	SELL	0	---	0
	Order	Iceberg	3	2	3	7	2	SELL	0	---	1
	Credits	7
	Credit	1	16
	Credit	2	11
	Credit	3	10
	Credit	4	8
	Credit	5	10
	Credit	6	14
	Credit	7	12
	Ownerships	7
	Ownership	1	93
	Ownership	2	76
	Ownership	3	56
	Ownership	4	22
	Ownership	5	68
	Ownership	6	56
	Ownership	7	93
	ReferencePrice	5
	StaticPriceBandLowerLimit	0.6
	StaticPriceBandUpperLimit	0.8
	TotalShares	100
	OwnershipUpperLimit	0.2
	TickSize	1
	LotSize	1
CancelOrderRs	Rejected
	Orders	2
	Order	Limit	1	4	1	4	4	SELL	0	---	0
	Order	Iceberg	3	2	3	7	2	SELL	0	---	1
	Credits	7
	Credit	1	16
	Credit	2	11
	Credit	3	10
	Credit	4	8
	Credit	5	10
	Credit	6	14
	Credit	7	12
	Ownerships	7
	Ownership	1	93
	Ownership	2	76
	Ownership	3	56
	Ownership	4	22
	Ownership	5	68
	Ownership	6	56
	Ownership	7	93
	ReferencePrice	5
	StaticPriceBandLowerLimit	0.6
	StaticPriceBandUpperLimit	0.8
	TotalShares	100
	OwnershipUpperLimit	0.2
	TickSize	1
	LotSize	1
Limit	6	4	7	5	5	SELL	0	---	0
NewOrderRs	Accepted
	Trades	0
	Orders	3
	Order	Limit	1	4	1	4	4	SELL	0	---	0
	Order	Limit	6	4	7	5	5	SELL	0	---	0
	Order	Iceberg	3	2	3	7	2	SELL	0	---	1
	Credits	7
	Credit	1	16
	Credit	2	11
	Credit	3	10
	Credit	4	8
	Credit	5	10
	Credit	6	14
	Credit	7	12
	Ownerships	7
	Ownership	1	93
	Ownership	2	76
	Ownership	3	56
	Ownership	4	22
	Ownership	5	68
	Ownership	6	56
	Ownership	7	93
	ReferencePrice	5
	StaticPriceBandLowerLimit	0.6
	StaticPriceBandUpperLimit	0.8
	TotalShares	100
	OwnershipUpperLimit	0.2
	TickSize	1
	LotSize	1
Limit	7	2	7	2	2	BUY 	0	FAK	0
NewOrderRs	Rejected
	Trades	0
	Orders	3
	Order	Limit	1	4	1	4	4	SELL	0	---	0
	Order	Limit	6	4	7	5	5	SELL	0	---	0
	Order	Iceberg	3	2	3	7	2	SELL	0	---	1
	Credits	7
	Credit	1	16
	Credit	2	11
	Credit	3	10
	Credit	4	8
	Credit	5	10
	Credit	6	14
	Credit	7	12
	Ownerships	7
	Ownership	1	93
	Ownership	2	76
	Ownership	3	56
	Ownership	4	22
	Ownership	5	68
	Ownership	6	56
	Ownership	7	93
	ReferencePrice	5
	StaticPriceBandLowerLimit	0.6
	StaticPriceBandUpperLimit	0.8
	TotalShares	100
	OwnershipUpperLimit	0.2
	TickSize	1
	LotSize	1
Iceberg	8	1	7	5	8	BUY 	0	---	0
NewOrderRs	Rejected
	Trades	0
	Orders	3
	Order	Limit	1	4	1	4	4	SELL	0	---	0
	Order	Limit	6	4	7	5	5	SELL	0	---	0
	Order	Iceberg	3	2	3	7	2	SELL	0	---	1
	Credits	7
	Credit	1	16
	Credit	2	11
	Credit	3	10
	Credit	4	8
	Credit	5	10
	Credit	6	14
	Credit	7	12
	Ownerships	7
	Ownership	1	93
	Ownership	2	76
	Ownership	3	56
	Ownership	4	22
	Ownership	5	68
	Ownership	6	56
	Ownership	7	93
	ReferencePrice	5
	StaticPriceBandLowerLimit	0.6
	StaticPriceBandUpperLimit	0.8
	TotalShares	100
	OwnershipUpperLimit	0.2
	TickSize	1
	LotSize	1
Limit	9	7	3	7	5	SELL	1	---	0
NewOrderRs	Eliminated
	Trades	0
	Orders	3
	Order	Limit	1	4	1	4	4	SELL	0	---	0
	Order	Limit	6	4	7	5	5	SELL	0	---	0
	Order	Iceberg	3	2	3	7	2	SELL	0	---	1
	Credits	7
	Credit	1	16
	Credit	2	11
	Credit	3	10
	Credit	4	8
	Credit	5	10
	Credit	6	14
	Credit	7	12
	Ownerships	7
	Ownership	1	93
	Ownership	2	76
	Ownership	3	56
	Ownership	4	22
	Ownership	5	68
	Ownership	6	56
	Ownership	7	93
	ReferencePrice	5
	StaticPriceBandLowerLimit	0.6
	StaticPriceBandUpperLimit	0.8
	TotalShares	100
	OwnershipUpperLimit	0.2
	TickSize	1
	LotSize	1
Limit	10	7	3	7	5	SELL	0	FAK	0
ReplaceOrderRs	Rejected
	Trades	0
	Orders	3
	Order	Limit	1	4	1	4	4	SELL	0	---	0
	Order	Limit	6	4	7	5	5	SELL	0	---	0
	Order	Iceberg	3	2	3	7	2	SELL	0	---	1
	Credits	7
	Credit	1	16
	Credit	2	11
	Credit	3	10
	Credit	4	8
	Credit	5	10
	Credit	6	14
	Credit	7	12
	Ownerships	7
	Ownership	1	93
	Ownership	2	76
	Ownership	3	56
	Ownership	4	22
	Ownership	5	68
	Ownership	6	56
	Ownership	7	93
	ReferencePrice	5
	StaticPriceBandLowerLimit	0.6
	StaticPriceBandUpperLimit	0.8
	TotalShares	100
	OwnershipUpperLimit	0.2
	TickSize	1
	LotSize	1
