reported_result/report-18/ART_WClustering/output/output33.txt

Limit	1	6	5	7	3	SELL	0	---	0
NewOrderRs	Accepted
	Trades	0
	Orders	1
	Order	Limit	1	6	5	7	3	SELL	0	---	0
	Credits	7
	Credit	1	13
	Credit	2	9
	Credit	3	19
	Credit	4	15
	Credit	5	11
	Credit	6	16
	Credit	7	6
	Ownerships	7
	Ownership	1	82
	Ownership	2	46
	Ownership	3	61
	Ownership	4	26
	Ownership	5	65
	Ownership	6	34
	Ownership	7	90
	ReferencePrice	5
	StaticPriceBandLowerLimit	0.6
	StaticPriceBandUpperLimit	0.8
	TotalShares	100
	OwnershipUpperLimit	0.2
	TickSize	1
	LotSize	1
Limit	2	3	2	3	2	SELL	0	---	0
NewOrderRs	Accepted
	Trades	0
	Orders	2
	Order	Limit	2	3	2	3	2	SELL	0	---	0
	Order	Limit	1	6	5	7	3	SELL	0	---	0
	Credits	7
	Credit	1	13
	Credit	2	9
	Credit	3	19
	Credit	4	15
	Credit	5	11
	Credit	6	16
	Credit	7	6
	Ownerships	7
	Ownership	1	82
	Ownership	2	46
	Ownership	3	61
	Ownership	4	26
	Ownership	5	65
	Ownership	6	34
	Ownership	7	90
	ReferencePrice	5
	StaticPriceBandLowerLimit	0.6
	StaticPriceBandUpperLimit	0.8
	TotalShares	100
	OwnershipUpperLimit	0.2
	TickSize	1
	LotSize	1
Iceberg	3	5	3	8	5	SELL	0	---	0
NewOrderRs	Accepted
	Trades	0
	Orders	3
	Order	Limit	2	3	2	3	2	SELL	0	---	0
	Order	Limit	1	6	5	7	3	SELL	0	---	0
	Order	Iceberg	3	5	3	8	5	SELL	0	---	1
	Credits	7
	Credit	1	13
	Credit	2	9
	Credit	3	19
	Credit	4	15
	Credit	5	11
	Credit	6	16
	Credit	7	6
	Ownerships	7
	Ownership	1	82
	Ownership	2	46
	Ownership	3	61
	Ownership	4	26
	Ownership	5	65
	Ownership	6	34
	Ownership	7	90
	ReferencePrice	5
	StaticPriceBandLowerLimit	0.6
	StaticPriceBandUpperLimit	0.8
	TotalShares	100
	OwnershipUpperLimit	0.2
	TickSize	1
	LotSize	1
Limit	4	6	6	8	1	BUY 	0	---	0
NewOrderRs	Rejected
	Trades	0
	Orders	3
	Order	Limit	2	3	2	3	2	SELL	0	---	0
	Order	Limit	1	6	5	7	3	SELL	0	---	0
	Order	Iceberg	3	5	3	8	5	SELL	0	---	1
	Credits	7
	Credit	1	13
	Credit	2	9
	Credit	3	19
	Credit	4	15
	Credit	5	11
	Credit	6	16
	Credit	7	6
	Ownerships	7
	Ownership	1	82
	Ownership	2	46
	Ownership	3	61
	Ownership	4	26
	Ownership	5	65
	Ownership	6	34
	Ownership	7	90
	ReferencePrice	5
	StaticPriceBandLowerLimit	0.6
	StaticPriceBandUpperLimit	0.8
	TotalShares	100
	OwnershipUpperLimit	0.2
	TickSize	1
	LotSize	1
CancelOrderRs	Rejected
	Orders	3
	Order	Limit	2	3	2	3	2	SELL	0	---	0
	Order	Limit	1	6	5	7	3	SELL	0	---	0
	Order	Iceberg	3	5	3	8	5	SELL	0	---	1
	Credits	7
	Credit	1	13
	Credit	2	9
	Credit	3	19
	Credit	4	15
	Credit	5	11
	Credit	6	16
	Credit	7	6
	Ownerships	7
	Ownership	1	82
	Ownership	2	46
	Ownership	3	61
	Ownership	4	26
	Ownership	5	65
	Ownership	6	34
	Ownership	7	90
	ReferencePrice	5
	StaticPriceBandLowerLimit	0.6
	StaticPriceBandUpperLimit	0.8
	TotalShares	100
	OwnershipUpperLimit	0.2
	TickSize	1
	LotSize	1
Limit	6	3	3	4	5	SELL	4	---	0
NewOrderRs	Eliminated
	Trades	0
	Orders	3
	Order	Limit	2	3	2	3	2	SELL	0	---	0
	Order	Limit	1	6	5	7	3	SELL	0	---	0
	Order	Iceberg	3	5	3	8	5	SELL	0	---	1
	Credits	7
	Credit	1	13
	Credit	2	9
	Credit	3	19
	Credit	4	15
	Credit	5	11
	Credit	6	16
	Credit	7	6
	Ownerships	7
	Ownership	1	82
	Ownership	2	46
	Ownership	3	61
	Ownership	4	26
	Ownership	5	65
	Ownership	6	34
	Ownership	7	90
	ReferencePrice	5
	StaticPriceBandLowerLimit	0.6
	StaticPriceBandUpperLimit	0.8
	TotalShares	100
	OwnershipUpperLimit	0.2
	TickSize	1
	LotSize	1
Limit	7	7	2	4	5	SELL	0	---	0
NewOrderRs	Accepted
	Trades	0
	Orders	4
	Order	Limit	2	3	2	3	2	SELL	0	---	0
	Order	Limit	7	7	2	4	5	SELL	0	---	0
	Order	Limit	1	6	5	7	3	SELL	0	---	0
	Order	Iceberg	3	5	3	8	5	SELL	0	---	1
	Credits	7
	Credit	1	13
	Credit	2	9
	Credit	3	19
	Credit	4	15
	Credit	5	11
	Credit	6	16
	Credit	7	6
	Ownerships	7
	Ownership	1	82
	Ownership	2	46
	Ownership	3	61
	Ownership	4	26
	Ownership	5	65
	Ownership	6	34
	Ownership	7	90
	ReferencePrice	5
	StaticPriceBandLowerLimit	0.6
	StaticPriceBandUpperLimit	0.8
	TotalShares	100
	OwnershipUpperLimit	0.2
	TickSize	1
	LotSize	1
Iceberg	8	5	7	3	2	BUY 	0	---	0
NewOrderRs	Rejected
	Trades	0
	Orders	4
	Order	Limit	2	3	2	3	2	SELL	0	---	0
	Order	Limit	7	7	2	4	5	SELL	0	---	0
	Order	Limit	1	6	5	7	3	SELL	0	---	0
	Order	Iceberg	3	5	3	8	5	SELL	0	---	1
	Credits	7
	Credit	1	13
	Credit	2	9
	Credit	3	19
	Credit	4	15
	Credit	5	11
	Credit	6	16
	Credit	7	6
	Ownerships	7
	Ownership	1	82
	Ownership	2	46
	Ownership	3	61
	Ownership	4	26
	Ownership	5	65
	Ownership	6	34
	Ownership	7	90
	ReferencePrice	5
	StaticPriceBandLowerLimit	0.6
	StaticPriceBandUpperLimit	0.8
	TotalShares	100
	OwnershipUpperLimit	0.2
	TickSize	1
	LotSize	1
Iceberg	9	3	7	8	1	BUY 	1	---	0
NewOrderRs	Rejected
	Trades	0
	Orders	4
	Order	Limit	2	3	2	3	2	SELL	0	---	0
	Order	Limit	7	7	2	4	5	SELL	0	---	0
	Order	Limit	1	6	5	7	3	SELL	0	---	0
	Order	Iceberg	3	5	3	8	5	SELL	0	---	1
	Credits	7
	Credit	1	13
	Credit	2	9
	Credit	3	19
	Credit	4	15
	Credit	5	11
	Credit	6	16
	Credit	7	6
	Ownerships	7
	Ownership	1	82
	Ownership	2	46
	Ownership	3	61
	Ownership	4	26
	Ownership	5	65
	Ownership	6	34
	Ownership	7	90
	ReferencePrice	5
	StaticPriceBandLowerLimit	0.6
	StaticPriceBandUpperLimit	0.8
	TotalShares	100
	OwnershipUpperLimit	0.2
	TickSize	1
	LotSize	1
Iceberg	10	3	7	6	1	BUY 	1	---	0
ReplaceOrderRs	Rejected
	Trades	0
	Orders	4
	Order	Limit	2	3	2	3	2	SELL	0	---	0
	Order	Limit	7	7	2	4	5	SELL	0	---	0
	Order	Limit	1	6	5	7	3	SELL	0	---	0
	Order	Iceberg	3	5	3	8	5	SELL	0	---	1
	Credits	7
	Credit	1	13
	Credit	2	9
	Credit	3	19
	Credit	4	15
	Credit	5	11
	Credit	6	16
	Credit	7	6
	Ownerships	7
	Ownership	1	82
	Ownership	2	46
	Ownership	3	61
	Ownership	4	26
	Ownership	5	65
	Ownership	6	34
	Ownership	7	90
	ReferencePrice	5
	StaticPriceBandLowerLimit	0.6
	StaticPriceBandUpperLimit	0.8
	TotalShares	100
	OwnershipUpperLimit	0.2
	TickSize	1
	LotSize	1
