reported_result/report-18/ART_WT/output/output4.txt

Iceberg	1	2	4	7	5	SELL	0	---	0
NewOrderRs	Accepted
	Trades	0
	Orders	1
	Order	Iceberg	1	2	4	7	5	SELL	0	---	3
	Credits	7
	Credit	1	18
	Credit	2	14
	Credit	3	6
	Credit	4	3
	Credit	5	12
	Credit	6	11
	Credit	7	16
	Ownerships	7
	Ownership	1	82
	Ownership	2	65
	Ownership	3	29
	Ownership	4	53
	Ownership	5	29
	Ownership	6	70
	Ownership	7	62
	ReferencePrice	5
	StaticPriceBandLowerLimit	0.6
	StaticPriceBandUpperLimit	0.8
	TotalShares	100
	OwnershipUpperLimit	0.2
	TickSize	1
	LotSize	1
Iceberg	2	2	7	7	4	SELL	0	---	0
NewOrderRs	Accepted
	Trades	0
	Orders	2
	Order	Iceberg	1	2	4	7	5	SELL	0	---	3
	Order	Iceberg	2	2	7	7	4	SELL	0	---	2
	Credits	7
	Credit	1	18
	Credit	2	14
	Credit	3	6
	Credit	4	3
	Credit	5	12
	Credit	6	11
	Credit	7	16
	Ownerships	7
	Ownership	1	82
	Ownership	2	65
	Ownership	3	29
	Ownership	4	53
	Ownership	5	29
	Ownership	6	70
	Ownership	7	62
	ReferencePrice	5
	StaticPriceBandLowerLimit	0.6
	StaticPriceBandUpperLimit	0.8
	TotalShares	100
	OwnershipUpperLimit	0.2
	TickSize	1
	LotSize	1
Iceberg	3	7	4	3	8	SELL	0	---	0
NewOrderRs	Accepted
	Trades	0
	Orders	3
	Order	Iceberg	3	7	4	3	8	SELL	0	---	1
	Order	Iceberg	1	2	4	7	5	SELL	0	---	3
	Order	Iceberg	2	2	7	7	4	SELL	0	---	2
	Credits	7
	Credit	1	18
	Credit	2	14
	Credit	3	6
	Credit	4	3
	Credit	5	12
	Credit	6	11
	Credit	7	16
	Ownerships	7
	Ownership	1	82
	Ownership	2	65
	Ownership	3	29
	Ownership	4	53
	Ownership	5	29
	Ownership	6	70
	Ownership	7	62
	ReferencePrice	5
	StaticPriceBandLowerLimit	0.6
	StaticPriceBandUpperLimit	0.8
	TotalShares	100
	OwnershipUpperLimit	0.2
	TickSize	1
	LotSize	1
Iceberg	4	3	2	1	3	SELL	3	---	0
NewOrderRs	Rejected
	Trades	0
	Orders	3
	Order	Iceberg	3	7	4	3	8	SELL	0	---	1
	Order	Iceberg	1	2	4	7	5	SELL	0	---	3
	Order	Iceberg	2	2	7	7	4	SELL	0	---	2
	Credits	7
	Credit	1	18
	Credit	2	14
	Credit	3	6
	Credit	4	3
	Credit	5	12
	Credit	6	11
	Credit	7	16
	Ownerships	7
	Ownership	1	82
	Ownership	2	65
	Ownership	3	29
	Ownership	4	53
	Ownership	5	29
	Ownership	6	70
	Ownership	7	62
	ReferencePrice	5
	StaticPriceBandLowerLimit	0.6
	StaticPriceBandUpperLimit	0.8
	TotalShares	100
	OwnershipUpperLimit	0.2
	TickSize	1
	LotSize	1
CancelOrderRs	Rejected
	Orders	3
	Order	Iceberg	3	7	4	3	8	SELL	0	---	1
	Order	Iceberg	1	2	4	7	5	SELL	0	---	3
	Order	Iceberg	2	2	7	7	4	SELL	0	---	2
	Credits	7
	Credit	1	18
	Credit	2	14
	Credit	3	6
	Credit	4	3
	Credit	5	12
	Credit	6	11
	Credit	7	16
	Ownerships	7
	Ownership	1	82
	Ownership	2	65
	Ownership	3	29
	Ownership	4	53
	Ownership	5	29
	Ownership	6	70
	Ownership	7	62
	ReferencePrice	5
	StaticPriceBandLowerLimit	0.6
	StaticPriceBandUpperLimit	0.8
	TotalShares	100
	OwnershipUpperLimit	0.2
	TickSize	1
	LotSize	1
Limit	6	3	4	7	7	SELL	0	---	0
NewOrderRs	Accepted
	Trades	0
	Orders	4
	Order	Iceberg	3	7	4	3	8	SELL	0	---	1
	Order	Iceberg	1	2	4	7	5	SELL	0	---	3
	Order	Iceberg	2	2	7	7	4	SELL	0	---	2
	Order	Limit	6	3	4	7	7	SELL	0	---	0
	Credits	7
	Credit	1	18
	Credit	2	14
	Credit	3	6
	Credit	4	3
	Credit	5	12
	Credit	6	11
	Credit	7	16
	Ownerships	7
	Ownership	1	82
	Ownership	2	65
	Ownership	3	29
	Ownership	4	53
	Ownership	5	29
	Ownership	6	70
	Ownership	7	62
	ReferencePrice	5
	StaticPriceBandLowerLimit	0.6
	StaticPriceBandUpperLimit	0.8
	TotalShares	100
	OwnershipUpperLimit	0.2
	TickSize	1
	LotSize	1
Limit	7	3	6	8	6	SELL	6	---	0
NewOrderRs	Eliminated
	Trades	0
	Orders	4
	Order	Iceberg	3	7	4	3	8	SELL	0	---	1
	Order	Iceberg	1	2	4	7	5	SELL	0	---	3
	Order	Iceberg	2	2	7	7	4	SELL	0	---	2
	Order	Limit	6	3	4	7	7	SELL	0	---	0
	Credits	7
	Credit	1	18
	Credit	2	14
	Credit	3	6
	Credit	4	3
	Credit	5	12
	Credit	6	11
	Credit	7	16
	Ownerships	7
	Ownership	1	82
	Ownership	2	65
	Ownership	3	29
	Ownership	4	53
	Ownership	5	29
	Ownership	6	70
	Ownership	7	62
	ReferencePrice	5
	StaticPriceBandLowerLimit	0.6
	StaticPriceBandUpperLimit	0.8
	TotalShares	100
	OwnershipUpperLimit	0.2
	TickSize	1
	LotSize	1
Limit	8	3	5	4	1	SELL	0	FAK	0
NewOrderRs	Eliminated
	Trades	0
	Orders	4
	Order	Iceberg	3	7	4	3	8	SELL	0	---	1
	Order	Iceberg	1	2	4	7	5	SELL	0	---	3
	Order	Iceberg	2	2	7	7	4	SELL	0	---	2
	Order	Limit	6	3	4	7	7	SELL	0	---	0
	Credits	7
	Credit	1	18
	Credit	2	14
	Credit	3	6
	Credit	4	3
	Credit	5	12
	Credit	6	11
	Credit	7	16
	Ownerships	7
	Ownership	1	82
	Ownership	2	65
	Ownership	3	29
	Ownership	4	53
	Ownership	5	29
	Ownership	6	70
	Ownership	7	62
	ReferencePrice	5
	StaticPriceBandLowerLimit	0.6
	StaticPriceBandUpperLimit	0.8
	TotalShares	100
	OwnershipUpperLimit	0.2
	TickSize	1
	LotSize	1
Limit	9	3	2	8	4	SELL	0	FAK	0
NewOrderRs	Eliminated
	Trades	0
	Orders	4
	Order	Iceberg	3	7	4	3	8	SELL	0	---	1
	Order	Iceberg	1	2	4	7	5	SELL	0	---	3
	Order	Iceberg	2	2	7	7	4	SELL	0	---	2
	Order	Limit	6	3	4	7	7	SELL	0	---	0
	Credits	7
	Credit	1	18
	Credit	2	14
	Credit	3	6
	Credit	4	3
	Credit	5	12
	Credit	6	11
	Credit	7	16
	Ownerships	7
	Ownership	1	82
	Ownership	2	65
	Ownership	3	29
	Ownership	4	53
	Ownership	5	29
	Ownership	6	70
	Ownership	7	62
	ReferencePrice	5
	StaticPriceBandLowerLimit	0.6
	StaticPriceBandUpperLimit	0.8
	TotalShares	100
	OwnershipUpperLimit	0.2
	TickSize	1
	LotSize	1
Iceberg	10	3	2	9	6	SELL	2	---	0
ReplaceOrderRs	Rejected
	Trades	0
	Orders	4
	Order	Iceberg	3	7	4	3	8	SELL	0	---	1
	Order	Iceberg	1	2	4	7	5	SELL	0	---	3
	Order	Iceberg	2	2	7	7	4	SELL	0	---	2
	Order	Limit	6	3	4	7	7	SELL	0	---	0
	Credits	7
	Credit	1	18
	Credit	2	14
	Credit	3	6
	Credit	4	3
	Credit	5	12
	Credit	6	11
	Credit	7	16
	Ownerships	7
	Ownership	1	82
	Ownership	2	65
	Ownership	3	29
	Ownership	4	53
	Ownership	5	29
	Ownership	6	70
	Ownership	7	62
	ReferencePrice	5
	StaticPriceBandLowerLimit	0.6
	StaticPriceBandUpperLimit	0.8
	TotalShares	100
	OwnershipUpperLimit	0.2
	TickSize	1
	LotSize	1
Iceberg	11	1	6	3	3	BUY 	1	---	0
NewOrderRs	Rejected
	Trades	0
	Orders	4
	Order	Iceberg	3	7	4	3	8	SELL	0	---	1
	Order	Iceberg	1	2	4	7	5	SELL	0	---	3
	Order	Iceberg	2	2	7	7	4	SELL	0	---	2
	Order	Limit	6	3	4	7	7	SELL	0	---	0
	Credits	7
	Credit	1	18
	Credit	2	14
	Credit	3	6
	Credit	4	3
	Credit	5	12
	Credit	6	11
	Credit	7	16
	Ownerships	7
	Ownership	1	82
	Ownership	2	65
	Ownership	3	29
	Ownership	4	53
	Ownership	5	29
	Ownership	6	70
	Ownership	7	62
	ReferencePrice	5
	StaticPriceBandLowerLimit	0.6
	StaticPriceBandUpperLimit	0.8
	TotalShares	100
	OwnershipUpperLimit	0.2
	TickSize	1
	LotSize	1
Iceberg	12	1	2	7	5	SELL	1	---	0
NewOrderRs	Eliminated
	Trades	0
	Orders	4
	Order	Iceberg	3	7	4	3	8	SELL	0	---	1
	Order	Iceberg	1	2	4	7	5	SELL	0	---	3
	Order	Iceberg	2	2	7	7	4	SELL	0	---	2
	Order	Limit	6	3	4	7	7	SELL	0	---	0
	Credits	7
	Credit	1	18
	Credit	2	14
	Credit	3	6
	Credit	4	3
	Credit	5	12
	Credit	6	11
	Credit	7	16
	Ownerships	7
	Ownership	1	82
	Ownership	2	65
	Ownership	3	29
	Ownership	4	53
	Ownership	5	29
	Ownership	6	70
	Ownership	7	62
	ReferencePrice	5
	StaticPriceBandLowerLimit	0.6
	StaticPriceBandUpperLimit	0.8
	TotalShares	100
	OwnershipUpperLimit	0.2
	TickSize	1
	LotSize	1
Limit	13	2	3	5	8	SELL	0	FAK	0
NewOrderRs	Eliminated
	Trades	0
	Orders	4
	Order	Iceberg	3	7	4	3	8	SELL	0	---	1
	Order	Iceberg	1	2	4	7	5	SELL	0	---	3
	Order	Iceberg	2	2	7	7	4	SELL	0	---	2
	Order	Limit	6	3	4	7	7	SELL	0	---	0
	Credits	7
	Credit	1	18
	Credit	2	14
	Credit	3	6
	Credit	4	3
	Credit	5	12
	Credit	6	11
	Credit	7	16
	Ownerships	7
	Ownership	1	82
	Ownership	2	65
	Ownership	3	29
	Ownership	4	53
	Ownership	5	29
	Ownership	6	70
	Ownership	7	62
	ReferencePrice	5
	StaticPriceBandLowerLimit	0.6
	StaticPriceBandUpperLimit	0.8
	TotalShares	100
	OwnershipUpperLimit	0.2
	TickSize	1
	LotSize	1
Limit	14	7	3	6	7	SELL	4	---	0
NewOrderRs	Eliminated
	Trades	0
	Orders	4
	Order	Iceberg	3	7	4	3	8	SELL	0	---	1
	Order	Iceberg	1	2	4	7	5	SELL	0	---	3
	Order	Iceberg	2	2	7	7	4	SELL	0	---	2
	Order	Limit	6	3	4	7	7	SELL	0	---	0
	Credits	7
	Credit	1	18
	Credit	2	14
	Credit	3	6
	Credit	4	3
	Credit	5	12
	Credit	6	11
	Credit	7	16
	Ownerships	7
	Ownership	1	82
	Ownership	2	65
	Ownership	3	29
	Ownership	4	53
	Ownership	5	29
	Ownership	6	70
	Ownership	7	62
	ReferencePrice	5
	StaticPriceBandLowerLimit	0.6
	StaticPriceBandUpperLimit	0.8
	TotalShares	100
	OwnershipUpperLimit	0.2
	TickSize	1
	LotSize	1
CancelOrderRs	Rejected
	Orders	4
	Order	Iceberg	3	7	4	3	8	SELL	0	---	1
